<sdf version='1.7'>
  <world name='default'>
    <light name='sun' type='directional'>
      <cast_shadows>1</cast_shadows>
      <pose>0 0 10 0 -0 0</pose>
      <diffuse>0.8 0.8 0.8 1</diffuse>
      <specular>0.2 0.2 0.2 1</specular>
      <attenuation>
        <range>1000</range>
        <constant>0.9</constant>
        <linear>0.01</linear>
        <quadratic>0.001</quadratic>
      </attenuation>
      <direction>-0.5 0.1 -0.9</direction>
      <spot>
        <inner_angle>0</inner_angle>
        <outer_angle>0</outer_angle>
        <falloff>0</falloff>
      </spot>
    </light>
    <model name='ground_plane'>
      <static>1</static>
      <link name='link'>
        <collision name='collision'>
          <geometry>
            <plane>
              <normal>0 0 1</normal>
              <size>100 100</size>
            </plane>
          </geometry>
          <surface>
            <friction>
              <ode>
                <mu>100</mu>
                <mu2>50</mu2>
              </ode>
              <torsional>
                <ode/>
              </torsional>
            </friction>
            <contact>
              <ode/>
            </contact>
            <bounce/>
          </surface>
          <max_contacts>10</max_contacts>
        </collision>
        <visual name='visual'>
          <cast_shadows>0</cast_shadows>
          <geometry>
            <plane>
              <normal>0 0 1</normal>
              <size>100 100</size>
            </plane>
          </geometry>
          <material>
            <script>
              <uri>file://media/materials/scripts/gazebo.material</uri>
              <name>Gazebo/Grey</name>
            </script>
          </material>
        </visual>
        <self_collide>0</self_collide>
        <enable_wind>0</enable_wind>
        <kinematic>0</kinematic>
      </link>
    </model>
    <gravity>0 0 -9.8</gravity>
    <magnetic_field>6e-06 2.3e-05 -4.2e-05</magnetic_field>
    <atmosphere type='adiabatic'/>
    <physics type='ode'>
      <max_step_size>0.001</max_step_size>
      <real_time_factor>1</real_time_factor>
      <real_time_update_rate>1000</real_time_update_rate>
    </physics>
    <scene>
      <ambient>0.4 0.4 0.4 1</ambient>
      <background>0.7 0.7 0.7 1</background>
      <shadows>1</shadows>
    </scene>
    <audio>
      <device>default</device>
    </audio>
    <wind/>
    <spherical_coordinates>
      <surface_model>EARTH_WGS84</surface_model>
      <latitude_deg>0</latitude_deg>
      <longitude_deg>0</longitude_deg>
      <elevation>0</elevation>
      <heading_deg>0</heading_deg>
    </spherical_coordinates>
    <model name='self_driving_car'>
      <link name='base_footprint'>
        <inertial>
          <pose>-1.0605 1.3e-05 0.304872 0 -0 0</pose>
          <mass>159.087</mass>
          <inertia>
            <ixx>11.2548</ixx>
            <ixy>-0.00011177</ixy>
            <ixz>0.179883</ixz>
            <iyy>5.2672</iyy>
            <iyz>4.01341e-05</iyz>
            <izz>10.5598</izz>
          </inertia>
        </inertial>
        <collision name='base_footprint_fixed_joint_lump__base_link_collision'>
          <pose>0 0 0.2 0 -0 0</pose>
          <geometry>
            <mesh>
              <scale>1 1 1</scale>
              <uri>file:///home/wafa/ackermann-Autonomous-Car-Simulation/install/Enimia_model/share/Enimia_model/meshes/base_link.STL</uri>
            </mesh>
          </geometry>
          <max_contacts>10</max_contacts>
          <surface>
            <contact>
              <ode/>
            </contact>
            <bounce/>
            <friction>
              <torsional>
                <ode/>
              </torsional>
              <ode/>
            </friction>
          </surface>
        </collision>
        <collision name='base_footprint_fixed_joint_lump__imu_link_collision_1'>
          <pose>0 0 0.21 0 -0 0</pose>
          <geometry>
            <box>
              <size>0.1 0.1 0.1</size>
            </box>
          </geometry>
          <surface>
            <contact>
              <ode/>
            </contact>
            <friction>
              <ode/>
              <torsional>
                <ode/>
              </torsional>
            </friction>
            <bounce/>
          </surface>
          <max_contacts>10</max_contacts>
        </collision>
        <collision name='base_footprint_fixed_joint_lump__velodyne_base_link_collision_2'>
          <pose>0 0 1.23 0 -0 0</pose>
          <geometry>
            <cylinder>
              <length>0.0717</length>
              <radius>0.0516</radius>
            </cylinder>
          </geometry>
          <max_contacts>10</max_contacts>
          <surface>
            <contact>
              <ode/>
            </contact>
            <bounce/>
            <friction>
              <torsional>
                <ode/>
              </torsional>
              <ode/>
            </friction>
          </surface>
        </collision>
        <collision name='base_footprint_fixed_joint_lump__zed_camera_link_collision_3'>
          <pose>0.6 0 0.8 0 -0 0</pose>
          <geometry>
            <box>
              <size>0.033 0.175 0.03</size>
            </box>
          </geometry>
          <surface>
            <contact>
              <ode/>
            </contact>
            <friction>
              <ode/>
              <torsional>
                <ode/>
              </torsional>
            </friction>
            <bounce/>
          </surface>
          <max_contacts>10</max_contacts>
        </collision>
        <visual name='base_footprint_fixed_joint_lump__base_link_visual'>
          <pose>0 0 0.2 0 -0 0</pose>
          <geometry>
            <mesh>
              <scale>1 1 1</scale>
              <uri>file:///home/wafa/ackermann-Autonomous-Car-Simulation/install/Enimia_model/share/Enimia_model/meshes/base_link.STL</uri>
            </mesh>
          </geometry>
        </visual>
        <visual name='base_footprint_fixed_joint_lump__imu_link_visual_1'>
          <pose>0 0 0.21 0 -0 0</pose>
          <geometry>
            <box>
              <size>0.1 0.1 0.1</size>
            </box>
          </geometry>
        </visual>
        <visual name='base_footprint_fixed_joint_lump__velodyne_base_link_visual_2'>
          <pose>0 0 1.05 0 -0 0</pose>
          <geometry>
            <mesh>
              <scale>1 1 1</scale>
              <uri>file:///home/wafa/ackermann-Autonomous-Car-Simulation/install/Enimia_model/share/Enimia_model/meshes/os1_64.dae</uri>
            </mesh>
          </geometry>
        </visual>
        <visual name='base_footprint_fixed_joint_lump__velodyne_base_link_visual_3'>
          <pose>0 0 1.05 0 -0 0</pose>
          <geometry>
            <cylinder>
              <length>0.073</length>
              <radius>0.04</radius>
            </cylinder>
          </geometry>
        </visual>
        <visual name='base_footprint_fixed_joint_lump__velodyne_visual_4'>
          <pose>0 0 1.05 0 -0 0</pose>
          <geometry>
            <cylinder>
              <length>0.073</length>
              <radius>0.04</radius>
            </cylinder>
          </geometry>
          <material>
            <script>
              <name>Gazebo/Black</name>
              <uri>file://media/materials/scripts/gazebo.material</uri>
            </script>
          </material>
        </visual>
        <visual name='base_footprint_fixed_joint_lump__zed_camera_link_visual_5'>
          <pose>0.6 0 0.8 0 -0 0</pose>
          <geometry>
            <box>
              <size>0.033 0.175 0.03</size>
            </box>
          </geometry>
          <material>
            <script>
              <name>Gazebo/Black</name>
              <uri>file://media/materials/scripts/gazebo.material</uri>
            </script>
          </material>
        </visual>
        <gravity>1</gravity>
        <sensor name='imu_sensor' type='imu'>
          <always_on>1</always_on>
          <update_rate>200</update_rate>
          <visualize>1</visualize>
          <topic>__default_topic__</topic>
          <plugin name='imu_plugin' filename='libgazebo_ros_imu_sensor.so'>
            <topicName>imu_raw</topicName>
            <update_rate>0</update_rate>
            <bodyName>imu_link</bodyName>
            <updateRateHZ>200.0</updateRateHZ>
            <gaussianNoise>0.0</gaussianNoise>
            <xyzOffset>0 0 0</xyzOffset>
            <rpyOffset>0 0 0</rpyOffset>
            <frameName>base_link</frameName>
            <initialOrientationAsReference>0</initialOrientationAsReference>
          </plugin>
          <pose>0 0 0.21 0 -0 0</pose>
          <imu/>
        </sensor>
        <sensor name='velodyne-VLP16' type='ray'>
          <visualize>0</visualize>
          <update_rate>10</update_rate>
          <ray>
            <scan>
              <horizontal>
                <samples>440</samples>
                <resolution>1</resolution>
                <min_angle>-3.14159</min_angle>
                <max_angle>3.14159</max_angle>
              </horizontal>
              <vertical>
                <samples>16</samples>
                <resolution>1</resolution>
                <min_angle>-0.261799</min_angle>
                <max_angle>0.261799</max_angle>
              </vertical>
            </scan>
            <range>
              <min>0.3</min>
              <max>131</max>
              <resolution>0.001</resolution>
            </range>
            <noise>
              <type>gaussian</type>
              <mean>0</mean>
              <stddev>0</stddev>
            </noise>
          </ray>
          <plugin name='gazebo_ros_laser_controller' filename='libgazebo_ros_velodyne_laser.so'>
            <topicName>/points_raw</topicName>
            <frameName>velodyne</frameName>
            <min_range>0.9</min_range>
            <max_range>130.0</max_range>
            <gaussianNoise>0.008</gaussianNoise>
          </plugin>
          <pose>0 0 1.0877 0 -0 0</pose>
        </sensor>
        <sensor name='zed2' type='depth'>
          <visualize>1</visualize>
          <update_rate>20</update_rate>
          <camera>
            <horizontal_fov>1.39626</horizontal_fov>
            <image>
              <width>640</width>
              <height>480</height>
              <format>R8G8B8</format>
            </image>
            <clip>
              <near>0.05</near>
              <far>20</far>
            </clip>
          </camera>
          <plugin name='camera_controller' filename='libgazebo_ros_camera.so'>
            <always_on>1</always_on>
            <frame_name>camera_link_optical</frame_name>
            <cameraName>Zed2</cameraName>
            <imageTopicName>zed/depth/image_raw</imageTopicName>
            <cameraInfoTopicName>zed/depth/camera_info</cameraInfoTopicName>
            <hackBaseline>0.07</hackBaseline>
            <distortionK1>0.0</distortionK1>
            <distortionK2>0.0</distortionK2>
            <distortionK3>0.0</distortionK3>
            <distortionT1>0.0</distortionT1>
            <distortionT2>0.0</distortionT2>
          </plugin>
          <pose>0.6 0 0.8 0 -0 0</pose>
        </sensor>
        <self_collide>0</self_collide>
        <enable_wind>0</enable_wind>
        <kinematic>0</kinematic>
      </link>
      <joint name='left_rear_axle' type='revolute'>
        <pose relative_to='base_footprint'>-0.9671 0.53474 0.1653 1.5708 -0 0</pose>
        <parent>base_footprint</parent>
        <child>left_rear_wheel</child>
        <axis>
          <xyz>0 0 -1</xyz>
          <limit>
            <effort>204.95</effort>
            <velocity>39.02</velocity>
            <lower>-1e+16</lower>
            <upper>1e+16</upper>
          </limit>
          <dynamics>
            <spring_reference>0</spring_reference>
            <spring_stiffness>0</spring_stiffness>
          </dynamics>
        </axis>
      </joint>
      <link name='left_rear_wheel'>
        <pose relative_to='left_rear_axle'>0 0 0 0 -0 0</pose>
        <inertial>
          <pose>0 0 0 0 -0 0</pose>
          <mass>8</mass>
          <inertia>
            <ixx>0.167285</ixx>
            <ixy>0</ixy>
            <ixz>0</ixz>
            <iyy>0.167285</iyy>
            <iyz>0</iyz>
            <izz>0.326036</izz>
          </inertia>
        </inertial>
        <collision name='left_rear_wheel_collision'>
          <pose>0 0 -0.08 0 -0 0</pose>
          <geometry>
            <cylinder>
              <length>0.08</length>
              <radius>0.285</radius>
            </cylinder>
          </geometry>
          <surface>
            <contact>
              <ode/>
            </contact>
            <friction>
              <ode/>
              <torsional>
                <ode/>
              </torsional>
            </friction>
            <bounce/>
          </surface>
          <max_contacts>10</max_contacts>
        </collision>
        <visual name='left_rear_wheel_visual'>
          <pose>0 0 -0.08 0 -0 0</pose>
          <geometry>
            <cylinder>
              <length>0.08</length>
              <radius>0.285</radius>
            </cylinder>
          </geometry>
          <material>
            <script>
              <name>Gazebo/Black</name>
              <uri>file://media/materials/scripts/gazebo.material</uri>
            </script>
          </material>
        </visual>
        <self_collide>0</self_collide>
        <enable_wind>0</enable_wind>
        <kinematic>0</kinematic>
      </link>
      <joint name='left_steering_joint' type='revolute'>
        <pose relative_to='base_footprint'>0.85903 0.44365 0.165 3.14159 1.57079 3.14159</pose>
        <parent>base_footprint</parent>
        <child>left_steering_link</child>
        <axis>
          <xyz>-1 0 0</xyz>
          <limit>
            <lower>-0.785398</lower>
            <upper>0.785398</upper>
            <effort>50</effort>
            <velocity>25</velocity>
          </limit>
          <dynamics>
            <spring_reference>0</spring_reference>
            <spring_stiffness>0</spring_stiffness>
          </dynamics>
        </axis>
      </joint>
      <link name='left_steering_link'>
        <pose relative_to='left_steering_joint'>0 0 0 0 -0 0</pose>
        <inertial>
          <pose>0 0 0 0 -0 0</pose>
          <mass>4.5</mass>
          <inertia>
            <ixx>0.001</ixx>
            <ixy>0</ixy>
            <ixz>0</ixz>
            <iyy>0.001</iyy>
            <iyz>0</iyz>
            <izz>0.001</izz>
          </inertia>
        </inertial>
        <self_collide>0</self_collide>
        <enable_wind>0</enable_wind>
        <kinematic>0</kinematic>
      </link>
      <joint name='left_front_axle' type='revolute'>
        <pose relative_to='left_steering_link'>0 0 0 1.5708 -0 0</pose>
        <parent>left_steering_link</parent>
        <child>left_front_wheel</child>
        <axis>
          <xyz>0 0 -1</xyz>
          <limit>
            <effort>204.95</effort>
            <velocity>39.02</velocity>
            <lower>-1e+16</lower>
            <upper>1e+16</upper>
          </limit>
          <dynamics>
            <spring_reference>0</spring_reference>
            <spring_stiffness>0</spring_stiffness>
          </dynamics>
        </axis>
      </joint>
      <link name='left_front_wheel'>
        <pose relative_to='left_front_axle'>0 0 0 0 -0 0</pose>
        <inertial>
          <pose>0 0 0 0 -0 0</pose>
          <mass>8</mass>
          <inertia>
            <ixx>0.167285</ixx>
            <ixy>0</ixy>
            <ixz>0</ixz>
            <iyy>0.167285</iyy>
            <iyz>0</iyz>
            <izz>0.326036</izz>
          </inertia>
        </inertial>
        <collision name='left_front_wheel_collision'>
          <pose>0 0 -0.08 0 -0 0</pose>
          <geometry>
            <cylinder>
              <length>0.08</length>
              <radius>0.285</radius>
            </cylinder>
          </geometry>
          <surface>
            <contact>
              <ode/>
            </contact>
            <friction>
              <ode/>
              <torsional>
                <ode/>
              </torsional>
            </friction>
            <bounce/>
          </surface>
          <max_contacts>10</max_contacts>
        </collision>
        <visual name='left_front_wheel_visual'>
          <pose>0 0 -0.08 0 -0 0</pose>
          <geometry>
            <cylinder>
              <length>0.08</length>
              <radius>0.285</radius>
            </cylinder>
          </geometry>
          <material>
            <script>
              <name>Gazebo/Black</name>
              <uri>file://media/materials/scripts/gazebo.material</uri>
            </script>
          </material>
        </visual>
        <self_collide>0</self_collide>
        <enable_wind>0</enable_wind>
        <kinematic>0</kinematic>
      </link>
      <joint name='right_rear_axle' type='revolute'>
        <pose relative_to='base_footprint'>-0.9671 -0.53474 0.1653 1.5708 -0 0</pose>
        <parent>base_footprint</parent>
        <child>right_rear_wheel</child>
        <axis>
          <xyz>0 0 -1</xyz>
          <limit>
            <effort>204.95</effort>
            <velocity>39.02</velocity>
            <lower>-1e+16</lower>
            <upper>1e+16</upper>
          </limit>
          <dynamics>
            <spring_reference>0</spring_reference>
            <spring_stiffness>0</spring_stiffness>
          </dynamics>
        </axis>
      </joint>
      <link name='right_rear_wheel'>
        <pose relative_to='right_rear_axle'>0 0 0 0 -0 0</pose>
        <inertial>
          <pose>0 0 0 0 -0 0</pose>
          <mass>8</mass>
          <inertia>
            <ixx>0.167285</ixx>
            <ixy>0</ixy>
            <ixz>0</ixz>
            <iyy>0.167285</iyy>
            <iyz>0</iyz>
            <izz>0.326036</izz>
          </inertia>
        </inertial>
        <collision name='right_rear_wheel_collision'>
          <pose>0 0 0.08 0 -0 0</pose>
          <geometry>
            <cylinder>
              <length>0.08</length>
              <radius>0.285</radius>
            </cylinder>
          </geometry>
          <surface>
            <contact>
              <ode/>
            </contact>
            <friction>
              <ode/>
              <torsional>
                <ode/>
              </torsional>
            </friction>
            <bounce/>
          </surface>
          <max_contacts>10</max_contacts>
        </collision>
        <visual name='right_rear_wheel_visual'>
          <pose>0 0 0.08 0 -0 0</pose>
          <geometry>
            <cylinder>
              <length>0.08</length>
              <radius>0.285</radius>
            </cylinder>
          </geometry>
          <material>
            <script>
              <name>Gazebo/Black</name>
              <uri>file://media/materials/scripts/gazebo.material</uri>
            </script>
          </material>
        </visual>
        <self_collide>0</self_collide>
        <enable_wind>0</enable_wind>
        <kinematic>0</kinematic>
      </link>
      <joint name='right_steering_joint' type='revolute'>
        <pose relative_to='base_footprint'>0.85903 -0.44365 0.165 3.14159 1.57079 3.14159</pose>
        <parent>base_footprint</parent>
        <child>right_steering_link</child>
        <axis>
          <xyz>-1 0 0</xyz>
          <limit>
            <lower>-0.785398</lower>
            <upper>0.785398</upper>
            <effort>50</effort>
            <velocity>25</velocity>
          </limit>
          <dynamics>
            <spring_reference>0</spring_reference>
            <spring_stiffness>0</spring_stiffness>
          </dynamics>
        </axis>
      </joint>
      <link name='right_steering_link'>
        <pose relative_to='right_steering_joint'>0 0 0 0 -0 0</pose>
        <inertial>
          <pose>0 0 0 0 -0 0</pose>
          <mass>4.5</mass>
          <inertia>
            <ixx>0.001</ixx>
            <ixy>0</ixy>
            <ixz>0</ixz>
            <iyy>0.001</iyy>
            <iyz>0</iyz>
            <izz>0.001</izz>
          </inertia>
        </inertial>
        <self_collide>0</self_collide>
        <enable_wind>0</enable_wind>
        <kinematic>0</kinematic>
      </link>
      <joint name='right_front_axle' type='revolute'>
        <pose relative_to='right_steering_link'>0 0 0 1.5708 -0 0</pose>
        <parent>right_steering_link</parent>
        <child>right_front_wheel</child>
        <axis>
          <xyz>0 0 -1</xyz>
          <limit>
            <effort>204.95</effort>
            <velocity>39.02</velocity>
            <lower>-1e+16</lower>
            <upper>1e+16</upper>
          </limit>
          <dynamics>
            <spring_reference>0</spring_reference>
            <spring_stiffness>0</spring_stiffness>
          </dynamics>
        </axis>
      </joint>
      <link name='right_front_wheel'>
        <pose relative_to='right_front_axle'>0 0 0 0 -0 0</pose>
        <inertial>
          <pose>0 0 0 0 -0 0</pose>
          <mass>8</mass>
          <inertia>
            <ixx>0.167285</ixx>
            <ixy>0</ixy>
            <ixz>0</ixz>
            <iyy>0.167285</iyy>
            <iyz>0</iyz>
            <izz>0.326036</izz>
          </inertia>
        </inertial>
        <collision name='right_front_wheel_collision'>
          <pose>0 0 0.08 0 -0 0</pose>
          <geometry>
            <cylinder>
              <length>0.08</length>
              <radius>0.285</radius>
            </cylinder>
          </geometry>
          <surface>
            <contact>
              <ode/>
            </contact>
            <friction>
              <ode/>
              <torsional>
                <ode/>
              </torsional>
            </friction>
            <bounce/>
          </surface>
          <max_contacts>10</max_contacts>
        </collision>
        <visual name='right_front_wheel_visual'>
          <pose>0 0 0.08 0 -0 0</pose>
          <geometry>
            <cylinder>
              <length>0.08</length>
              <radius>0.285</radius>
            </cylinder>
          </geometry>
          <material>
            <script>
              <name>Gazebo/Black</name>
              <uri>file://media/materials/scripts/gazebo.material</uri>
            </script>
          </material>
        </visual>
        <self_collide>0</self_collide>
        <enable_wind>0</enable_wind>
        <kinematic>0</kinematic>
      </link>
      <static>0</static>
      <plugin name='gazebo_ros_ackermann_drive' filename='libgazebo_ros_ackermann_drive.so'>
        <ros>
          <remapping>cmd_vel:=cmd_vel</remapping>
          <remapping>odom:=odom</remapping>
        </ros>
        <update_rate>100.0</update_rate>
        <front_left_joint>left_front_axle</front_left_joint>
        <front_right_joint>right_front_axle</front_right_joint>
        <rear_left_joint>left_rear_axle</rear_left_joint>
        <rear_right_joint>right_rear_axle</rear_right_joint>
        <left_steering_joint>left_steering_joint</left_steering_joint>
        <right_steering_joint>right_steering_joint</right_steering_joint>
        <max_steer>1.01</max_steer>
        <max_steering_angle>6.85</max_steering_angle>
        <max_speed>20</max_speed>
        <left_steering_pid_gain>1500 0 1</left_steering_pid_gain>
        <left_steering_i_range>0 0</left_steering_i_range>
        <right_steering_pid_gain>1500 0 1</right_steering_pid_gain>
        <right_steering_i_range>0 0</right_steering_i_range>
        <linear_velocity_pid_gain>1000 0 1</linear_velocity_pid_gain>
        <linear_velocity_i_range>0 0</linear_velocity_i_range>
        <publish_odom>1</publish_odom>
        <publish_odom_tf>1</publish_odom_tf>
        <publish_wheel_tf>1</publish_wheel_tf>
        <publish_distance>0</publish_distance>
        <odometry_frame>odom</odometry_frame>
        <robot_base_frame>base_footprint</robot_base_frame>
      </plugin>
      <pose>0 0 0.5 0 -0 0</pose>
    </model>
    <model name='custom_track_section'>
      <static>1</static>
      <link name='track_link'>
        <visual name='road_visual'>
          <geometry>
            <plane>
              <normal>0 0 1</normal>
              <size>20 4</size>
            </plane>
          </geometry>
          <material>
            <script>
              <uri>file://media/materials/scripts/gazebo.material</uri>
              <name>Gazebo/DarkAsphalt</name>
            </script>
          </material>
        </visual>
        <visual name='left_line_visual'>
          <pose>0 2.01 0.01 0 -0 0</pose>
          <geometry>
            <plane>
              <normal>0 0 1</normal>
              <size>20 0.1</size>
            </plane>
          </geometry>
          <material>
            <script>
              <uri>file://media/materials/scripts/gazebo.material</uri>
              <name>Gazebo/White</name>
            </script>
          </material>
        </visual>
        <visual name='right_line_visual'>
          <pose>0 -2.01 0.01 0 -0 0</pose>
          <geometry>
            <plane>
              <normal>0 0 1</normal>
              <size>20 0.1</size>
            </plane>
          </geometry>
          <material>
            <script>
              <uri>file://media/materials/scripts/gazebo.material</uri>
              <name>Gazebo/White</name>
            </script>
          </material>
        </visual>
        <visual name='left_barrier'>
          <pose>0 2.5 0.5 0 -0 0</pose>
          <geometry>
            <box>
              <size>20 0.2 0.5</size>
            </box>
          </geometry>
          <material>
            <script>
              <uri>file://media/materials/scripts/gazebo.material</uri>
              <name>Gazebo/Red</name>
            </script>
          </material>
        </visual>
        <visual name='right_barrier'>
          <pose>0 -2.5 0.5 0 -0 0</pose>
          <geometry>
            <box>
              <size>20 0.2 0.5</size>
            </box>
          </geometry>
          <material>
            <script>
              <uri>file://media/materials/scripts/gazebo.material</uri>
              <name>Gazebo/Red</name>
            </script>
          </material>
        </visual>
        <self_collide>0</self_collide>
        <enable_wind>0</enable_wind>
        <kinematic>0</kinematic>
      </link>
      <pose>4.12495 0.529428 0 0 -0 0</pose>
    </model>
    <state world_name='default'>
      <sim_time>63 443000000</sim_time>
      <real_time>69 595592892</real_time>
      <wall_time>1739891646 296895094</wall_time>
      <iterations>63443</iterations>
      <model name='custom_track_section'>
        <pose>4.12495 0.529428 0 0 -0 0</pose>
        <scale>1 1 1</scale>
        <link name='track_link'>
          <pose>4.12495 0.529428 0 0 -0 0</pose>
          <velocity>0 0 0 0 -0 0</velocity>
          <acceleration>0 0 0 0 -0 0</acceleration>
          <wrench>0 0 0 0 -0 0</wrench>
        </link>
      </model>
      <model name='self_driving_car'>
        <pose>-0.001712 -0.022654 0.119858 -8e-06 -0.000166 -0.018823</pose>
        <scale>1 1 1</scale>
        <link name='base_footprint'>
          <pose>-0.001712 -0.022654 0.119858 -8e-06 -0.000166 -0.018823</pose>
          <velocity>-0.000591 -0.003337 -0.005615 -0.00871 0.002318 -0.000654</velocity>
          <acceleration>0.025633 0.715101 -9.07644 -1.45881 0.295961 -0.129862</acceleration>
          <wrench>4.07791 113.763 -1443.94 0 -0 0</wrench>
        </link>
        <link name='left_front_wheel'>
          <pose>0.865489 0.40475 0.284996 -1.57086 1.32033 3.12275</pose>
          <velocity>8.7e-05 -0.002535 -0.011301 -0.005731 0.006282 0.000441</velocity>
          <acceleration>0.048909 0.273902 -10.3022 -2.21185 0.159604 -0.002701</acceleration>
          <wrench>0.391274 2.19121 -82.4174 0 -0 0</wrench>
        </link>
        <link name='left_rear_wheel'>
          <pose>-0.958603 0.530194 0.284994 1.57077 0.105284 -0.018826</pose>
          <velocity>0.000169 -0.00095 -0.00836 -0.004013 0.000718 -0.000714</velocity>
          <acceleration>0.046954 0.408691 -9.81499 -2.38188 0.044835 -0.256653</acceleration>
          <wrench>0.375633 3.26953 -78.5199 0 -0 0</wrench>
        </link>
        <link name='left_steering_link'>
          <pose>0.865489 0.40475 0.284996 0.188238 1.57063 0.169456</pose>
          <velocity>8.7e-05 -0.002588 -0.011293 -0.005851 0.002237 0.000424</velocity>
          <acceleration>0.050652 0.289167 -10.322 1.36646 0.520797 0.002478</acceleration>
          <wrench>0.227936 1.30125 -46.4488 0 -0 0</wrench>
        </link>
        <link name='right_front_wheel'>
          <pose>0.848788 -0.482393 0.285002 -1.57085 1.33962 3.12274</pose>
          <velocity>-0.000505 -0.002429 -0.003282 0.000525 -0.000198 0.002463</velocity>
          <acceleration>-0.114742 0.365057 -8.68965 -0.708989 0.131474 -0.002731</acceleration>
          <wrench>-0.917937 2.92046 -69.5172 0 -0 0</wrench>
        </link>
        <link name='right_rear_wheel'>
          <pose>-0.978733 -0.539092 0.285003 1.57082 -0.033979 -0.018824</pose>
          <velocity>-0.000514 -0.001886 0.001021 -0.015694 -0.002057 -0.000607</velocity>
          <acceleration>-0.076525 -0.860948 -8.55254 -0.1698 -0.059446 -0.263678</acceleration>
          <wrench>-0.612202 -6.88759 -68.4203 0 -0 0</wrench>
        </link>
        <link name='right_steering_link'>
          <pose>0.848788 -0.482393 0.285003 -0.104749 1.57064 -0.123545</pose>
          <velocity>-0.000505 -0.00243 -0.00336 -0.012784 0.002248 0.002457</velocity>
          <acceleration>-0.086996 0.307559 -8.82549 0.797291 0.150462 0.046762</acceleration>
          <wrench>-0.39148 1.38402 -39.7147 0 -0 0</wrench>
        </link>
      </model>
      <model name='ground_plane'>
        <pose>0 0 0 0 -0 0</pose>
        <scale>1 1 1</scale>
        <link name='link'>
          <pose>0 0 0 0 -0 0</pose>
          <velocity>0 0 0 0 -0 0</velocity>
          <acceleration>0 0 0 0 -0 0</acceleration>
          <wrench>0 0 0 0 -0 0</wrench>
        </link>
      </model>
      <light name='sun'>
        <pose>0 0 10 0 -0 0</pose>
      </light>
    </state>
    <gui fullscreen='0'>
      <camera name='user_camera'>
        <pose>13.2254 -12.0901 4.80181 0 0.275643 2.35619</pose>
        <view_controller>orbit</view_controller>
        <projection_type>perspective</projection_type>
      </camera>
    </gui>
  </world>
</sdf>
